Workbook

Sheet 在册班组
A1: 序号 | B1: 班组注册编号 | C1: 班组注册时间 | D1: 单位 | E1: 部门 | F1: 分包单位 | G1: 分包负责人和联系电话 | H1: 班组名称 | I1: 班长姓名和联系电话 | J1: 部门/队推进者 | K1: 监督人员 | L1: 工程公司推进者 | M1: 工程公司推进队办 | N1: 当前状态 | O1: 班组人数 | P1: 班组成员信息
P2: 姓名 | Q2: 性别 | R2: 身份证号码 | S2: 年龄 | T2: 工种 | U2: 职务 | V2: 用工形式 （自有/非自有） | W2: 进入班组时间 | X2: 离开班组时间 | Y2: 状态 （在职/离职） | Z2: 备注 | AA2: 是否重复 （姓名） | AB2: 是否重复 （sfz）
A3: 1 | B3: BLE-NCES-002 | C3: 44012 | D3: 中建二局 | E3: 核岛一队 | F3: 茂名建筑集团第三有限公司（专业分包） | G3: 杨亚堂15013858223 | H3: 高春芳机械班 | I3: 高春芳/18377073085 | J3: =_xlfn.XLOOKUP(H3,班组推进者!D:D,班组推进者!H:H,0) -> 莫锦华 | K3: =_xlfn.XLOOKUP(H3,班组推进者!D:D,班组推进者!I:I,0) -> 张晨雨 | N3: 在册 | O3: =_xlfn.XLOOKUP(H:H,[1]班组信息!$D:$D,[1]班组信息!$L:$L,0) -> 27 | P3: 高春芳 | Q3: 女 | R3: 452822197205034829 | S3: 54 | T3: 杂工 | U3: 班组长 | V3: 非自有 | W3: 42961
A4: 2 | B4: BLE-NCES-003 | C4: 45261 | D4: 中建二局 | E4: 搅拌站 | F4: 中南国际科技发展(深圳)有限公司 | G4: / | H4: 陈爱荣综合班 | I4: 陈爱荣/18877000991 | J4: =_xlfn.XLOOKUP(H4,班组推进者!D:D,班组推进者!H:H,0) -> 汪宇雄、魏智广 | K4: =_xlfn.XLOOKUP(H4,班组推进者!D:D,班组推进者!I:I,0) -> 赵鹏飞 | N4: 在册 | O4: =_xlfn.XLOOKUP(H:H,[1]班组信息!$D:$D,[1]班组信息!$L:$L,0) -> 22 | P4: 陈爱荣 | Q4: 男 | R4: 432930197312013515 | S4: 52 | T4: 驾驶员 | U4: 班组长 | V4: 自有 | W4: 42663 | Y4: 在职 | Z4: 作业负责人
A5: 3 | B5: BLE-NCES-004 | C5: 45916 | D5: 中建二局 | E5: 搅拌站 | F5: 中南国际科技发展(深圳)有限公司 | G5: / | H5: 杨广雄操作班 | I5: 杨广雄/19077008920 | J5: =_xlfn.XLOOKUP(H5,班组推进者!D:D,班组推进者!H:H,0) -> 朱其星 | K5: =_xlfn.XLOOKUP(H5,班组推进者!D:D,班组推进者!I:I,0) -> 陈柱旭 | N5: 在册 | O5: =_xlfn.XLOOKUP(H:H,[1]班组信息!$D:$D,[1]班组信息!$L:$L,0) -> 12 | P5: 杨广雄 | Q5: 男 | R5: 450602198408225111 | S5: 40 | T5: 机械操作工 | U5: 班组长 | V5: 自有 | W5: 2025.7.16 | X5: / | Y5: 在职 | Z5: 班组长
A6: 4 | B6: BLE-NCES-005 | C6: 45427 | D6: 中建二局 | E6: 水电队 | F6: 中国建筑第二工程局有限公司 | G6: / | H6: 吴再胜综合班 | I6: 吴再胜/13907709136 | J6: =_xlfn.XLOOKUP(H6,班组推进者!D:D,班组推进者!H:H,0) -> 齐张燕 | K6: =_xlfn.XLOOKUP(H6,班组推进者!D:D,班组推进者!I:I,0) -> 罗荣鑫 | N6: 在册 | O6: =_xlfn.XLOOKUP(H:H,[1]班组信息!$D:$D,[1]班组信息!$L:$L,0) -> 7 | P6: 吴再胜 | Q6: 男 | R6: 450602197109074814 | S6: =YEAR(TODAY())-MID(R6,7,4) -> 55 | T6: 管工 | U6: 班组长 | V6: 自有 | W6: 42639 | Y6: 在职 | Z6: 作业负责人
A7: 5 | B7: BLE-NCES-006 | C7: 45699 | D7: 中建二局 | E7: 核岛一队 | F7: 四川金泰荣和建筑劳务有限公司 | G7: 李传志18877002381 | H7: 吴运华装修班 | I7: 吴运华/18577058334 | J7: =_xlfn.XLOOKUP(H7,班组推进者!D:D,班组推进者!H:H,0) -> 罗福耀 | K7: =_xlfn.XLOOKUP(H7,班组推进者!D:D,班组推进者!I:I,0) -> 杨兆龙 | N7: 在册 | O7: =_xlfn.XLOOKUP(H:H,[1]班组信息!$D:$D,[1]班组信息!$L:$L,0) -> 12 | P7: 吴运华 | Q7: 男 | R7: 500234200006239573 | S7: 24 | T7: 清洁工 | U7: 班组长 | V7: 非自有 | W7: 45133 | Y7: 在职 | Z7: 班组长
A8: 6 | B8: BLE-NCES-009 | C8: 45733 | D8: 中建二局 | E8: 核岛一队 | F8: 四川金泰荣和建筑劳务有限公司 | G8: 李传志18877002381 | H8: 周小红装修班 | I8: 周小红/13877017861 | J8: =_xlfn.XLOOKUP(H8,班组推进者!D:D,班组推进者!H:H,0) -> 莫锦华 | K8: =_xlfn.XLOOKUP(H8,班组推进者!D:D,班组推进者!I:I,0) -> 罗荣鑫 | N8: 在册 | O8: =_xlfn.XLOOKUP(H:H,[1]班组信息!$D:$D,[1]班组信息!$L:$L,0) -> 16 | P8: 周小红 | Q8: 女 | R8: 452122197903042721 | S8: 45 | T8: 装修工 | U8: 班组长 | V8: 非自有 | W8: 2024.12.20 | Y8: 在职 | Z8: 班组长
A9: 7 | B9: BLE-NCES-010 | C9: 45785 | D9: 中建二局 | E9: 钢结构队 | F9: 中国建筑第二工程局有限公司 | G9: / | H9: 任炫烨焊工班 | I9: 任炫烨/15938968955 | J9: =_xlfn.XLOOKUP(H9,班组推进者!D:D,班组推进者!H:H,0) -> 范永宾 | K9: =_xlfn.XLOOKUP(H9,班组推进者!D:D,班组推进者!I:I,0) -> 魏成志 | N9: 在册 | O9: =_xlfn.XLOOKUP(H:H,[1]班组信息!$D:$D,[1]班组信息!$L:$L,0) -> 15 | P9: 任炫烨 | Q9: 男 | R9: 410482199910281731 | S9: 26 | T9: 焊工 | U9: 班组长 | V9: 自有 | W9: 2025.5.6 | X9: / | Y9: 在职 | Z9: 班组长
A10: 8 | B10: BLE-NCES-012 | C10: 45785 | D10: 中建二局 | E10: 核岛一队 | F10: 四川金泰荣和建筑劳务有限公司 | G10: 王家纯13828002135 | H10: 柏世尧木工班 | I10: 柏世尧/19132127818 | J10: =_xlfn.XLOOKUP(H10,班组推进者!D:D,班组推进者!H:H,0) -> 欧育顺 | K10: =_xlfn.XLOOKUP(H10,班组推进者!D:D,班组推进者!I:I,0) -> 刘友三 | N10: 在册 | O10: =_xlfn.XLOOKUP(H:H,[1]班组信息!$D:$D,[1]班组信息!$L:$L,0) -> 27 | P10: 柏世尧 | Q10: 男 | R10: 512224196510237376 | S10: 59 | T10: 综合管理 | U10: 班组长 | V10: 非自有 | W10: 2025.5.6 | Y10: 在职 | Z10: 班组长
A11: 9 | B11: BLE-NCES-013 | C11: 45785 | D11: 中建二局 | E11: 机械队 | F11: 四川德鑫隆建筑劳务有限公司 | G11: 田小刚13828016316 | H11: 田小刚塔吊班 | I11: 田小刚13828016316 | J11: =_xlfn.XLOOKUP(H11,班组推进者!D:D,班组推进者!H:H,0) -> 赵强强、徐官保 | K11: =_xlfn.XLOOKUP(H11,班组推进者!D:D,班组推进者!I:I,0) -> 龚天顺 | N11: 在册 | O11: =_xlfn.XLOOKUP(H:H,[1]班组信息!$D:$D,[1]班组信息!$L:$L,0) -> 34 | P11: 田小刚 | Q11: 男 | R11: 510902198206021535 | S11: 43 | T11: 塔吊指挥 | U11: 班组长 | V11: 非自有 | W11: 45765 | X11: / | Y11: 在职 | Z11: 班组长
A12: 10 | B12: BLE-NCES-014 | C12: 45906 | D12: 中建二局 | E12: 核岛一队 | F12: 四川金泰荣和建筑劳务有限公司 | G12: 孙俊良/13828741588 | H12: 夏凤勇架工班 | I12: 夏凤勇/18314471196（注销） | J12: =_xlfn.XLOOKUP(H12,班组推进者!D:D,班组推进者!H:H,0) -> 张富 | K12: =_xlfn.XLOOKUP(H12,班组推进者!D:D,班组推进者!I:I,0) -> 唐星民 | N12: 在册 | O12: =_xlfn.XLOOKUP(H:H,[1]班组信息!$D:$D,[1]班组信息!$L:$L,0) -> 27 | P12: 夏凤勇 | Q12: 男 | R12: 532122198612130611 | S12: 38 | T12: 架子工 | U12: 班组长 | V12: 自有 | W12: 45989 | Y12: 在职 | Z12: 班组长
A13: 11 | B13: BLE-NCES-015 | C13: 45785 | D13: 中建二局 | E13: 核岛一队 | F13: 四川金泰荣和建筑劳务有限公司 | G13: 孙俊良13828741588 | H13: 樊共辉架工班 | I13: 樊共辉/18877015163（注销） | J13: =_xlfn.XLOOKUP(H13,班组推进者!D:D,班组推进者!H:H,0) -> 张富 | K13: =_xlfn.XLOOKUP(H13,班组推进者!D:D,班组推进者!I:I,0) -> 李胜朝 | N13: 在册 | O13: =_xlfn.XLOOKUP(H:H,[1]班组信息!$D:$D,[1]班组信息!$L:$L,0) -> 33 | P13: 樊共辉 | Q13: 男 | R13: 432524197706097417 | S13: 47 | T13: 架子工 | U13: 班组长 | V13: 非自有 | W13: 2025.4.29 | Y13: 在职 | Z13: 班组长
A14: 12 | B14: BLE-NCES-016 | C14: 45785 | D14: 中建二局 | E14: 核岛一队 | F14: 四川金泰荣和建筑劳务有限公司 | G14: 王家纯13828002135 | H14: 罗春才钢筋班 | I14: 罗春才/18077013236 | J14: =_xlfn.XLOOKUP(H14,班组推进者!D:D,班组推进者!H:H,0) -> 曲殿英、周雷 | K14: =_xlfn.XLOOKUP(H14,班组推进者!D:D,班组推进者!I:I,0) -> 果机吃沙 | N14: 在册 | O14: =_xlfn.XLOOKUP(H:H,[1]班组信息!$D:$D,[1]班组信息!$L:$L,0) -> 50 | P14: 罗春才 | Q14: 男 | R14: 452428198408062716 | S14: 41 | T14: 钢筋工 | U14: 班组长 | V14: 非自有 | W14: 2025.9.3 | Y14: 在职 | Z14: 班组长
A15: 13 | B15: BLE-NCES-017 | C15: 45785 | D15: 中建二局 | E15: 综合车间 | F15: 广州盛通建筑劳务有限公司 | G15: 陈历权/13517538609 | H15: 陈历坤木工班 | I15: 陈历坤/18877009352 | J15: =_xlfn.XLOOKUP(H15,班组推进者!D:D,班组推进者!H:H,0) -> 吴祖基、韦伴锋 | K15: =_xlfn.XLOOKUP(H15,班组推进者!D:D,班组推进者!I:I,0) -> 魏成志 | N15: 在册 | O15: =_xlfn.XLOOKUP(H:H,[1]班组信息!$D:$D,[1]班组信息!$L:$L,0) -> 40 | P15: 陈历坤 | Q15: 男 | R15: 450324199202162211 | S15: 43 | T15: 木工 | U15: 班组长 | V15: 非自有 | X15: / | Y15: 在职 | Z15: 班组长
A16: 14 | B16: BLE-NCES-019 | C16: 45957 | D16: 中建二局 | E16: 综合车间 | F16: 广州盛通建筑劳务有限公司 | G16: 张剑富/13750368918 | H16: 王明清钢筋班 | I16: 王明清/13288771566 | J16: =_xlfn.XLOOKUP(H16,班组推进者!D:D,班组推进者!H:H,0) -> 张剑华 | K16: =_xlfn.XLOOKUP(H16,班组推进者!D:D,班组推进者!I:I,0) -> 李煊民 | N16: 在册 | O16: =_xlfn.XLOOKUP(H:H,[1]班组信息!$D:$D,[1]班组信息!$L:$L,0) -> 38 | P16: 王明清 | Q16: 男 | R16: 350426198002155519 | S16: 45 | T16: 钢筋工 | U16: 班组长 | V16: 非自有 | W16: 2025.10.14 | X16: / | Y16: 在职 | Z16: 班组长
A17: 15 | B17: BLE-NCES-020 | C17: 45811 | D17: 中建二局 | E17: 核岛一队 | F17: 四川金泰荣和建筑劳务有限公司 | G17: 王家纯13828002135 | H17: 李贤军混凝土班 | I17: 李贤军/13617709120 | J17: =_xlfn.XLOOKUP(H17,班组推进者!D:D,班组推进者!H:H,0) -> 张久风 | K17: =_xlfn.XLOOKUP(H17,班组推进者!D:D,班组推进者!I:I,0) -> 李修 | N17: 在册 | O17: =_xlfn.XLOOKUP(H:H,[1]班组信息!$D:$D,[1]班组信息!$L:$L,0) -> 26 | P17: 李贤军 | Q17: 男 | R17: 512222197306108739 | S17: 52 | T17: 混凝土工 | U17: 班组长 | V17: 非自有 | W17: 2025.5.8 | Y17: 在职 | Z17: 班组长
A18: 16 | B18: BLE-NCES-021 | C18: 45816 | D18: 中建二局 | E18: 钢结构队 | F18: 河南诚云建筑劳务有限公司 | G18: 张海云/13828019069 | H18: 刘强埋件班 | I18: 刘强/18434797612 | J18: =_xlfn.XLOOKUP(H18,班组推进者!D:D,班组推进者!H:H,0) -> 甘昌锦 | K18: =_xlfn.XLOOKUP(H18,班组推进者!D:D,班组推进者!I:I,0) -> 魏成志 | N18: 在册 | O18: =_xlfn.XLOOKUP(H:H,[1]班组信息!$D:$D,[1]班组信息!$L:$L,0) -> 38 | P18: 刘强 | Q18: 男 | R18: 142601197707292857 | S18: 48 | T18: 铆工 | U18: 班组长 | V18: 非自有 | W18: 45816 | X18: / | Y18: 在职 | Z18: 班组长
A19: 17 | B19: BLE-NCES-022 | C19: 45846 | D19: 中建二局 | E19: 钢结构队 | F19: 广西三卓建筑劳务有限公司（劳务分包） | G19: 钟光荣/13877247210 | H19: 杨霜霜铆工班 | I19: 杨霜霜/18208423203 | J19: =_xlfn.XLOOKUP(H19,班组推进者!D:D,班组推进者!H:H,0) -> 刘源、李波 | K19: =_xlfn.XLOOKUP(H19,班组推进者!D:D,班组推进者!I:I,0) -> 吕育祥 | N19: 在册 | O19: =_xlfn.XLOOKUP(H:H,[1]班组信息!$D:$D,[1]班组信息!$L:$L,0) -> 26 | P19: 杨霜霜 | Q19: 男 | R19: 522130199004281216 | S19: 35 | T19: 铆工 | U19: 班组长 | V19: 非自有 | W19: 45846 | X19: / | Y19: 在职 | Z19: 班组长
A20: 18 | B20: BLE-NCES-023 | C20: 45855 | D20: 中建二局 | E20: 机械队 | F20: 北京万古恒信科技有限公司（劳务分包） | G20: / | H20: 王增军机械班 | I20: 王增军/13878188986 | J20: =_xlfn.XLOOKUP(H20,班组推进者!D:D,班组推进者!H:H,0) -> 冉术林 | K20: =_xlfn.XLOOKUP(H20,班组推进者!D:D,班组推进者!I:I,0) -> 谭小飞 | N20: 在册 | O20: =_xlfn.XLOOKUP(H:H,[1]班组信息!$D:$D,[1]班组信息!$L:$L,0) -> 28 | P20: 王增军 | Q20: 男 | R20: 410928196907156134 | S20: =YEAR(TODAY())-MID(R20,7,4) -> 57 | T20: 司机 | U20: 班组长 | V20: 自有 | W20: 45855 | X20: / | Y20: 在职 | Z20: 班组长
A21: 19 | B21: BLE-NCES-024 | C21: 45863 | D21: 中建二局 | E21: 钢结构队 | F21: 河南核源建筑工程有限公司（劳务分包） | G21: 刘金骜/1857897783 | H21: 王昌松铆工班 | I21: 王昌松/18530667338 | J21: =_xlfn.XLOOKUP(H21,班组推进者!D:D,班组推进者!H:H,0) -> 范永宾 | K21: =_xlfn.XLOOKUP(H21,班组推进者!D:D,班组推进者!I:I,0) -> 吕育祥 | N21: 在册 | O21: =_xlfn.XLOOKUP(H:H,[1]班组信息!$D:$D,[1]班组信息!$L:$L,0) -> 38 | P21: 王昌松 | Q21: 男 | R21: 411324198901105311 | S21: 36 | T21: 铆工 | U21: 班组长 | V21: 非自有 | X21: / | Y21: 在职 | Z21: 班组长
A22: 20 | B22: BLE-NCES-025 | C22: 45863 | D22: 中建二局 | E22: 钢结构队 | F22: 深圳市帕玛泰克斯涂料有限公司 | G22: 陆亚春/18675070070 | H22: 郑创国油漆班 | I22: 郑创国/18476678793 | J22: =_xlfn.XLOOKUP(H22,班组推进者!D:D,班组推进者!H:H,0) -> 甘昌锦 | K22: =_xlfn.XLOOKUP(H22,班组推进者!D:D,班组推进者!I:I,0) -> 吕育祥 | N22: 在册 | O22: =_xlfn.XLOOKUP(H:H,[1]班组信息!$D:$D,[1]班组信息!$L:$L,0) -> 15 | P22: 郑创国 | Q22: 男 | R22: 440804198910021116 | S22: 35 | T22: 综合管理 | U22: 班组长 | V22: 非自有 | W22: 45862 | X22: / | Y22: 在职 | Z22: 班组长
A23: 21 | B23: BLE-NCES-026 | C23: 45875 | D23: 中建二局 | E23: 测量队 | F23: 北京万古恒信科技有限公司（劳务分包） | G23: / | H23: 李发强测量班 | I23: 李发强/18882509059 | J23: =_xlfn.XLOOKUP(H23,班组推进者!D:D,班组推进者!H:H,0) -> 吴坤鹏、李世忠 | K23: =_xlfn.XLOOKUP(H23,班组推进者!D:D,班组推进者!I:I,0) -> 谢博鑫 | N23: 在册 | O23: =_xlfn.XLOOKUP(H:H,[1]班组信息!$D:$D,[1]班组信息!$L:$L,0) -> 14 | P23: 李发强 | Q23: 男 | R23: 511023199704272490 | S23: =YEAR(TODAY())-MID(R23,7,4) -> 29 | T23: 测量员 | U23: 班组长 | V23: 自有 | X23: / | Y23: 在职 | Z23: 班组长
A24: 22 | B24: BLE-NCES-027 | C24: 45942 | D24: 中建二局 | E24: 核岛一队 | F24: 四川博瑞恒升建设工程有限公司（劳务分包） | G24: 李俊寰/15882955233 | H24: 张良钢筋班 | I24: 张良/13929061803 | J24: =_xlfn.XLOOKUP(H24,班组推进者!D:D,班组推进者!H:H,0) -> 魏垚 | K24: =_xlfn.XLOOKUP(H24,班组推进者!D:D,班组推进者!I:I,0) -> 朱凡康 | N24: 在册 | O24: =_xlfn.XLOOKUP(H:H,[1]班组信息!$D:$D,[1]班组信息!$L:$L,0) -> 40 | P24: 张良 | Q24: 男 | R24: 513022197410141934 | S24: 50 | T24: 钢筋工 | U24: 班组长 | V24: 非自有 | W24: 45910 | X24: / | Y24: 在职 | Z24: 班组长
A25: 23 | B25: BLE-NCES-028 | C25: 45888 | D25: 中建二局 | E25: 核岛一队 | F25: 四川博瑞恒升建设工程有限公司（劳务分包） | G25: 李俊寰/15882955233 | H25: 李涛木工班 | I25: 李涛/18977848984（注销） | J25: =_xlfn.XLOOKUP(H25,班组推进者!D:D,班组推进者!H:H,0) -> 王奋泽 | K25: =_xlfn.XLOOKUP(H25,班组推进者!D:D,班组推进者!I:I,0) -> 桂杨 | N25: 在册 | O25: =_xlfn.XLOOKUP(H:H,[1]班组信息!$D:$D,[1]班组信息!$L:$L,0) -> 27 | P25: 李涛 | Q25: 男 | R25: 622827198410050957 | S25: 41 | T25: 木工 | U25: 班组长 | V25: 非自有 | W25: 45986 | X25: / | Y25: 在职 | Z25: 班组长
A26: 24 | B26: BLE-NCES-029 | C26: 45903 | D26: 中建二局 | E26: 核岛一队 | F26: 嘉兴珅汇建筑安装工程有限公司 | G26: 牟道俊13906836538 | H26: 冯海录钢筋班 | I26: 冯海录/15296593282 | J26: =_xlfn.XLOOKUP(H26,班组推进者!D:D,班组推进者!H:H,0) -> 梁冬杰、欧育顺 | K26: =_xlfn.XLOOKUP(H26,班组推进者!D:D,班组推进者!I:I,0) -> 唐星民 | N26: 在册 | O26: =_xlfn.XLOOKUP(H:H,[1]班组信息!$D:$D,[1]班组信息!$L:$L,0) -> 35 | P26: 冯海录 | Q26: 男 | R26: 450621198207102333 | S26: 43 | T26: 钢筋工 | U26: 班组长 | V26: 非自有 | W26: 2025.8.20 | Y26: 在职 | Z26: 班组长
A27: 25 | B27: BLE-NCES-030 | C27: 45903 | D27: 中建二局 | E27: 核岛一队 | F27: 四川金泰荣和建筑劳务有限公司 | G27: 王家纯13828002135 | H27: 蓝碧情钢筋班 | I27: 蓝碧情/13828019204 | J27: =_xlfn.XLOOKUP(H27,班组推进者!D:D,班组推进者!H:H,0) -> 魏垚 | K27: =_xlfn.XLOOKUP(H27,班组推进者!D:D,班组推进者!I:I,0) -> 罗园杰 | N27: 在册 | O27: =_xlfn.XLOOKUP(H:H,[1]班组信息!$D:$D,[1]班组信息!$L:$L,0) -> 54 | P27: 蓝碧情 | Q27: 男 | R27: 452730198708276810 | S27: 38 | T27: 综合管理 | U27: 班组长 | V27: 非自有 | W27: 2025.8.28 | Y27: 在职 | Z27: 班组长
A28: 26 | B28: BLE-NCES-031 | C28: 45903 | D28: 中建二局 | E28: 核岛一队 | F28: 四川金泰荣和建筑劳务有限公司 | G28: 王家纯13828002135 | H28: 余应康混凝土班 | I28: 余应康/13759070538 | J28: =_xlfn.XLOOKUP(H28,班组推进者!D:D,班组推进者!H:H,0) -> 张久风 | K28: =_xlfn.XLOOKUP(H28,班组推进者!D:D,班组推进者!I:I,0) -> 蓝竫熙 | N28: 在册 | O28: =_xlfn.XLOOKUP(H:H,[1]班组信息!$D:$D,[1]班组信息!$L:$L,0) -> 16 | P28: 余应康 | Q28: 男 | R28: 532425197503201610 | S28: 50 | T28: 混凝土工 | U28: 班组长 | V28: 非自有 | W28: 2025.5.19 | Y28: 在职 | Z28: 班组长
A29: 27 | B29: BLE-NCES-034 | C29: 45911 | D29: 中建二局 | E29: 核岛一队 | F29: 嘉兴珅汇建筑安装工程有限公司 | G29: 牟道俊13906836538 | H29: 张强木工班 | I29: 张强/13678239050 | J29: =_xlfn.XLOOKUP(H29,班组推进者!D:D,班组推进者!H:H,0) -> 王奋泽 | K29: =_xlfn.XLOOKUP(H29,班组推进者!D:D,班组推进者!I:I,0) -> 宁以源 | N29: 在册 | O29: =_xlfn.XLOOKUP(H:H,[1]班组信息!$D:$D,[1]班组信息!$L:$L,0) -> 21 | P29: 张强 | Q29: 男 | R29: 510722197602032375 | S29: 49 | T29: 木工 | U29: 班组长 | V29: 非自有 | W29: 2025.8.31 | Y29: 在职 | Z29: 班组长
A30: 28 | B30: BLE-NCES-035 | C30: 45916 | D30: 中建二局 | E30: 搅拌站 | F30: 新国线集团 | G30: 罗时元13885656233 | H30: 罗时元运输班 | I30: 罗时元13885656233 | J30: =_xlfn.XLOOKUP(H30,班组推进者!D:D,班组推进者!H:H,0) -> 朱其星 | K30: =_xlfn.XLOOKUP(H30,班组推进者!D:D,班组推进者!I:I,0) -> 冯海浪 | N30: 在册 | O30: =_xlfn.XLOOKUP(H:H,[1]班组信息!$D:$D,[1]班组信息!$L:$L,0) -> 13 | P30: 罗时元 | Q30: 男 | R30: 522222198501261233 | S30: 40 | T30: 综合管理 | U30: 班组长 | V30: 非自有 | W30: 2025.8.20 | X30: / | Y30: 在职 | Z30: 班组长
A31: 29 | B31: BLE-NCES-036 | C31: 45916 | D31: 中建二局 | E31: 核岛一队 | F31: 嘉兴珅汇建筑安装工程有限公司 | G31: 牟道俊13906836538 | H31: 谢红均钢筋班 | I31: 谢红均/13252331612 | J31: =_xlfn.XLOOKUP(H31,班组推进者!D:D,班组推进者!H:H,0) -> 魏垚 | K31: =_xlfn.XLOOKUP(H31,班组推进者!D:D,班组推进者!I:I,0) -> 刘友三 | N31: 在册 | O31: =_xlfn.XLOOKUP(H:H,[1]班组信息!$D:$D,[1]班组信息!$L:$L,0) -> 33 | P31: 谢红均 | Q31: 男 | R31: 510723199005293898 | S31: 35 | T31: 钢筋工 | U31: 班组长 | V31: 非自有 | W31: 2025.8.31 | Y31: 在职 | Z31: 班组长
A32: 31 | B32: BLE-NCES-039 | C32: 45942 | D32: 中建二局 | E32: 核岛一队 | F32: 四川博瑞恒升建设工程有限公司（劳务分包） | G32: 李俊寰/15882955233 | H32: 杨勇发钢筋班 | I32: 杨勇发/18608035528（离职） | J32: =_xlfn.XLOOKUP(H32,班组推进者!D:D,班组推进者!H:H,0) -> 李慧武、程伟 | K32: =_xlfn.XLOOKUP(H32,班组推进者!D:D,班组推进者!I:I,0) -> 谢博鑫 | N32: 在册 | O32: =_xlfn.XLOOKUP(H:H,[1]班组信息!$D:$D,[1]班组信息!$L:$L,0) -> 30 | P32: 杨勇发 | Q32: 男 | R32: 51108119821025331X | S32: 43 | T32: 钢筋工 | U32: 班组长 | V32: 非自有 | W32: 45915 | X32: / | Y32: 离职 | Z32: 班组长
A33: 32 | B33: BLE-NCES-040 | C33: 45951 | D33: 中建二局 | E33: 核岛一队 | F33: 四川金泰荣和建筑劳务有限公司 | G33: 孙俊良13828741588 | H33: 李蕾架工班 | I33: 李蕾/19191112992 | J33: =_xlfn.XLOOKUP(H33,班组推进者!D:D,班组推进者!H:H,0) -> 张富 | K33: =_xlfn.XLOOKUP(H33,班组推进者!D:D,班组推进者!I:I,0) -> 李胜朝 | N33: 在册 | O33: =_xlfn.XLOOKUP(H:H,[1]班组信息!$D:$D,[1]班组信息!$L:$L,0) -> 26 | P33: 李蕾 | Q33: 男 | R33: 61240119860102413X | S33: 39 | T33: 架子工 | U33: 班组长 | V33: 非自有 | W33: 2025.7.2 | Y33: 在职 | Z33: 班组长
A34: 33 | B34: BLE-NCES-041 | C34: 45954 | D34: 中建二局 | E34: 钢结构队 | F34: 河南诚云建筑劳务有限公司 | G34: 张海云/13828019069 | H34: 李刚铆工班 | I34: 李刚/13978041991 | J34: =_xlfn.XLOOKUP(H34,班组推进者!D:D,班组推进者!H:H,0) -> 李斌、蔡彪 | K34: =_xlfn.XLOOKUP(H34,班组推进者!D:D,班组推进者!I:I,0) -> 龚天顺 | N34: 在册 | O34: =_xlfn.XLOOKUP(H:H,[1]班组信息!$D:$D,[1]班组信息!$L:$L,0) -> 37 | P34: 李刚 | Q34: 男 | R34: 450204198103231036 | S34: 44 | T34: 铆工 | U34: 班组长 | V34: 非自有 | W34: 2025.8.14 | Y34: 在职 | Z34: 班组长
A35: 34 | B35: BLE-NCES-042 | C35: 45957 | D35: 中建二局 | E35: 核岛一队 | F35: 四川金泰荣和建筑劳务有限公司 | G35: 王家纯13828002135 | H35: 罗长文木工班 | I35: 罗长文/14793899760 | J35: =_xlfn.XLOOKUP(H35,班组推进者!D:D,班组推进者!H:H,0) -> 谭咏杰 | K35: =_xlfn.XLOOKUP(H35,班组推进者!D:D,班组推进者!I:I,0) -> 张晨雨 | N35: 在册 | O35: =_xlfn.XLOOKUP(H:H,[1]班组信息!$D:$D,[1]班组信息!$L:$L,0) -> 33 | P35: 罗长文 | Q35: 男 | R35: 452223198705101512 | S35: 38 | T35: 木工 | U35: 班组长 | V35: 非自有 | W35: 45892 | Y35: 在职 | Z35: 班组长
A36: 35 | B36: BLE-NCES-043 | C36: 45961 | D36: 中建二局 | E36: 核岛一队 | F36: 四川博瑞恒升建设工程有限公司（劳务分包） | G36: 李俊寰/15882955233 | H36: 唐小强混凝土班 | I36: 唐小强/18140477517 | J36: =_xlfn.XLOOKUP(H36,班组推进者!D:D,班组推进者!H:H,0) -> 何贵华 | K36: =_xlfn.XLOOKUP(H36,班组推进者!D:D,班组推进者!I:I,0) -> 朱凡康 | N36: 在册 | O36: =_xlfn.XLOOKUP(H:H,[1]班组信息!$D:$D,[1]班组信息!$L:$L,0) -> 27 | P36: 唐小强 | Q36: 男 | R36: 511023196808300392 | S36: 57 | T36: 混凝土工 | U36: 班组长 | V36: 非自有 | W36: 45914 | X36: / | Y36: 在职 | Z36: 班组长
A37: 36 | B37: BLE-NCES-045 | C37: 45981 | D37: 中建二局 | E37: 机械队 | F37: 四川德鑫隆建筑劳务有限公司 | G37: 田小刚13828016316 | H37: 杨勇起重班 | I37: 杨勇/13691981249 | J37: =_xlfn.XLOOKUP(H37,班组推进者!D:D,班组推进者!H:H,0) -> 徐官保 | K37: =_xlfn.XLOOKUP(H37,班组推进者!D:D,班组推进者!I:I,0) -> 谭小飞 | N37: 在册 | O37: =_xlfn.XLOOKUP(H:H,[1]班组信息!$D:$D,[1]班组信息!$L:$L,0) -> 11 | P37: 杨勇 | Q37: 男 | R37: 511023198301222670 | S37: {=_xlfn.IFS(LEN(R37)=15,DATEDIF(TEXT("19"&MID(R37,7,6),"0-00-00"),TODAY(),"y"),LEN(R37)=18,DATEDIF(TEXT(MID(R37,7,8),"0-00-00"),TODAY(),"y"),TRUE,"身份证错误")} -> 43 | T37: 其他起重工 | U37: 班组长 | V37: 非自有 | W37: 2025.9.229 | Y37: 在职 | Z37: 班组长
A38: 37 | B38: BLE-NCES-046 | C38: 46011 | D38: 中建二局 | E38: 核岛一队 | F38: 四川金泰荣和建筑劳务有限公司 | G38: 王家纯/13828002135 | H38: 佟桂华清扫班 | I38: 佟桂华/15777965285 | J38: =_xlfn.XLOOKUP(H38,班组推进者!D:D,班组推进者!H:H,0) -> 陈柱旭 | K38: =_xlfn.XLOOKUP(H38,班组推进者!D:D,班组推进者!I:I,0) -> 陈柱旭 | N38: 在册 | O38: =_xlfn.XLOOKUP(H:H,[1]班组信息!$D:$D,[1]班组信息!$L:$L,0) -> 7 | P38: 佟桂华 | Q38: 女 | R38: 220281197404141822 | S38: 51 | T38: 清扫工 | U38: 班组长 | V38: 非自有 | W38: 45979 | Y38: 在职 | Z38: 班组长
A39: 38 | B39: BLE-NCES-047 | C39: 45994 | D39: 中建二局 | E39: 钢结构队 | F39: 广西三卓建筑劳务有限公司（劳务分包） | G39: 钟光荣/13877247210 | H39: 杨永昌铆工班 | I39: 杨永昌/13703808985 | J39: =_xlfn.XLOOKUP(H39,班组推进者!D:D,班组推进者!H:H,0) -> 甘昌锦 | K39: =_xlfn.XLOOKUP(H39,班组推进者!D:D,班组推进者!I:I,0) -> 李煊民 | N39: 在册 | O39: =_xlfn.XLOOKUP(H:H,[1]班组信息!$D:$D,[1]班组信息!$L:$L,0) -> 34 | P39: 杨永昌 | Q39: 男 | R39: 412827198812110511 | S39: 37 | T39: 钳工/铆工 | U39: 班组长 | V39: 非自有 | W39: 45994 | Y39: 在职 | Z39: 班组长
A40: 39 | B40: BLE-NCES-048 | C40: 46001 | D40: 中建二局 | E40: 核岛一队 | F40: 北京东方雨虹防水工程有限公司 | G40: 李立峰18526540106 | H40: 谢亮防水班 | I40: 谢亮17749655585 | J40: =_xlfn.XLOOKUP(H40,班组推进者!D:D,班组推进者!H:H,0) -> 宁凯 | K40: =_xlfn.XLOOKUP(H40,班组推进者!D:D,班组推进者!I:I,0) -> 桂杨 | N40: 在册 | O40: =_xlfn.XLOOKUP(H:H,[1]班组信息!$D:$D,[1]班组信息!$L:$L,0) -> 7 | P40: 谢亮 | Q40: 男 | R40: 430422200204280259 | S40: 24 | T40: 防水工 | U40: 班组长 | V40: 非自有 | W40: 2026.12.14 | Y40: 在职 | Z40: 班组长
...

Sheet 注销班组
A1: 序号 | B1: 班组注册编号 | C1: 班组注册时间 | D1: 单位 | E1: 部门 | F1: 所属分包 | G1: 分包负责人和联系电话 | H1: 班组名称 | I1: 班长姓名和联系电话 | J1: 部门/队推进者 | K1: 责任安全员 | L1: 当前状态 | M1: 班组分级 | N1: 评分（基础分85） | O1: 班组人数 | P1: 班组成员信息
P2: 姓名 | Q2: 性别 | R2: 身份证号码 | S2: 年龄 | T2: 工种 | U2: 职务 | V2: 用工形式 （自有/非自有） | W2: 进入班组时间 | X2: 离开班组时间 | Y2: 状态 （在职/离职） | Z2: 备注 | AA2: 是否重复 （姓名） | AB2: 是否重复 （sfz）
A3: 1 | B3: BLE-NCES-032 | C3: 45903 | D3: 中建二局 | E3: 核岛一队 | F3: 四川博瑞恒升建设工程有限公司（劳务分包） | G3: 李俊寰/15882955233 | H3: 王宇钢筋班 | I3: 王宇/18577811333 | J3: 李伟康 | K3: 蔡毅豪 | L3: 注销 | M3: Ⅰ类 | N3: / | O3: 0 | P3: 王宇 | Q3: 男 | R3: 429005196808138316 | S3: 57 | T3: 钢筋工 | U3: 班组长 | V3: 非自有 | X3: / | Y3: 离职 | Z3: （2026.03.10注销）
A4: 2 | B4: BLE-NCES-038 | C4: 45942 | D4: 中建二局 | E4: 核岛一队 | F4: 四川博瑞恒升建设工程有限公司（劳务分包） | G4: 李俊寰/15882955233 | H4: 谭传明木工班 | I4: 谭传明/19289089849 | J4: 李伟康 | K4: 桂杨 | L4: 注销 | M4: Ⅰ类 | N4: / | O4: 0 | P4: 谭传明 | Q4: 男 | R4: 512222197203048737 | S4: 53 | T4: 木工 | U4: 班组长 | V4: 非自有 | W4: 45912 | X4: / | Y4: 在职 | Z4: 注销时间2026.03.09
A5: 3 | B5: BLE-NCES-044 | C5: 45968 | D5: 中建二局 | E5: 搅拌站 | F5: 广东名城建设有限公司 | G5: 陈历权13517538609 | H5: 李可安装班 | I5: 李可13793768840 | K5: 张晨雨 | L5: 注销 | M5: / | N5: / | O5: 0 | P5: 李可 | Q5: 男 | R5: 370829199104182517 | S5: 34 | T5: 班组长 | U5: 班组长 | V5: 非自有 | X5: / | Y5: 离职
A6: 4 | B6: BLE-NCES-037 | C6: 45916 | D6: 中建二局 | E6: 核岛一队 | F6: 四川博瑞恒升建设工程有限公司（劳务分包） | G6: 李俊寰/15882955233 | H6: 邹新春木工班 | I6: 邹新春/19973890989 | J6: 黄龙骄 | K6: 杨兆龙 | L6: 在册 | M6: 20 | N6: 邹新春 | O6: 男 | P6: 432503197912177694 | Q6: 46 | R6: 木工 | S6: 班组长 | T6: 非自有 | U6: 2025.11.5 | V6: / | W6: 在职 | X6: 班组长

Sheet 班组推进者
A1: 班组推进者台账
A2: 序号 | B2: 班组注册编号 | C2: 部门 | D2: 班组名称 | E2: 班长姓名和联系电话 | F2: 分包单位 | G2: 分包负责人和联系电话 | H2: 部门/队推进者 | I2: 监督人员 | J2: 备注
A3: 1 | B3: BLE-NCES-016 | C3: 核岛一队 | D3: 罗春才钢筋班 | E3: 罗春才/18077013236 | F3: 四川金泰荣和建筑劳务有限公司 | G3: 王家纯13828002135 | H3: 曲殿英、周雷 | I3: 果机吃沙
A4: 2 | B4: BLE-NCES-029 | C4: 核岛一队 | D4: 冯海录钢筋班 | E4: 冯海录/15296593282 | F4: 嘉兴珅汇建筑安装工程有限公司 | G4: 牟道俊13906836538 | H4: 梁冬杰、欧育顺 | I4: 唐星民
A5: 3 | B5: BLE-NCES-017 | C5: 综合车间 | D5: 陈历坤木工班 | E5: 陈历坤/18877009352 | F5: 广州盛通建筑劳务有限公司 | G5: 陈历权/13517538609 | H5: 吴祖基、韦伴锋 | I5: 魏成志
A6: 4 | B6: BLE-NCES-052 | C6: 核岛一队 | D6: 钟绍林木工班 | E6: 钟绍林/13219597969 | F6: 四川金泰荣和建筑劳务有限公司 | G6: 王家纯/13828002135 | H6: 张翔、段龙飞 | I6: 刘友三
A7: 5 | B7: BLE-NCES-041 | C7: 钢结构队 | D7: 李刚铆工班 | E7: 李刚/13978041991 | F7: 河南诚云建筑劳务有限公司 | G7: 张海云/13828019069 | H7: 李斌、蔡彪 | I7: 龚天顺
A8: 6 | B8: BLE-NCES-039 | C8: 核岛一队 | D8: 杨勇发钢筋班 | E8: 杨勇发/18608035528 | F8: 四川博瑞恒升建设工程有限公司（劳务分包） | G8: 李俊寰/15882955233 | H8: 李慧武、程伟 | I8: 谢博鑫
A9: 7 | B9: BLE-NCES-022 | C9: 钢结构队 | D9: 杨霜霜铆工班 | E9: 杨霜霜/18208423203 | F9: 广西三卓建筑劳务有限公司（劳务分包） | G9: 钟光荣/13877247210 | H9: 刘源、李波 | I9: 吕育祥
A10: 8 | B10: BLE-NCES-003 | C10: 搅拌站 | D10: 陈爱荣综合班 | E10: 陈爱荣/18877000991 | F10: 中南国际科技发展(深圳)有限公司 | G10: / | H10: 汪宇雄、魏智广 | I10: 赵鹏飞
A11: 9 | B11: BLE-NCES-013 | C11: 机械队 | D11: 田小刚塔吊班 | E11: 田小刚13828016316 | F11: 四川德鑫隆建筑劳务有限公司 | G11: 田小刚13828016316 | H11: 赵强强、徐官保 | I11: 龚天顺
A12: 10 | B12: BLE-NCES-026 | C12: 测量队 | D12: 李发强测量班 | E12: 李发强/18882509059 | F12: 北京万古恒信科技有限公司（劳务分包） | G12: / | H12: 吴坤鹏、李世忠 | I12: 谢博鑫
A13: 11 | B13: BLE-NCES-021 | C13: 钢结构队 | D13: 刘强埋件班 | E13: 刘强/18434797612 | F13: 河南诚云建筑劳务有限公司 | G13: 张海云/13828019069 | H13: 甘昌锦 | I13: 魏成志
A14: 12 | B14: BLE-NCES-010 | C14: 钢结构队 | D14: 任炫烨焊工班 | E14: 任炫烨/15938968955 | F14: 中国建筑第二工程局有限公司 | G14: / | H14: 范永宾 | I14: 魏成志
... A54: 52 | B54: BLE-NCES-061 | C54: 核岛一队 | D54: 冉启伟钢筋班 | E54: 冉启伟/18881871005 | F54: 四川博瑞恒升建设工程有限公司 | G54: 李俊寰/15882955233 | H54: 王奋泽 | I54: 莫晓东
D55: 邓远华木工班 | H55: 段龙飞
D56: 杜恒江钢筋班 | H56: 王奋泽

Sheet 在退役项目班组台账
A1: 序号 | B1: 班组注册编号 | C1: 班组注册时间 | D1: 单位 | E1: 部门 | F1: 分包单位 | G1: 分包负责人和联系电话 | H1: 班组名称 | I1: 班长姓名和联系电话 | J1: 部门/队推进者 | K1: 监督人员 | L1: 工程公司推进者 | M1: 工程公司推进队办 | N1: 当前状态 | O1: 班组人数 | P1: 班组成员信息
P2: 姓名 | Q2: 性别 | R2: 身份证号码 | S2: 年龄 | T2: 工种 | U2: 职务 | V2: 用工形式 （自有/非自有） | W2: 进入班组时间 | X2: 离开班组时间 | Y2: 状态 （在职/离职） | Z2: 备注 | AA2: 是否重复 （姓名） | AB2: 是否重复 （sfz）
A3: 1 | B3: BLE-NCES-001 | C3: 46112 | D3: 中建二局 | E3: 工程部 | F3: 中国建筑第二工程局有限公司 | G3: / | H3: 吴再胜综合班 | I3: 吴再胜/13907709136 | J3: =_xlfn.XLOOKUP(H3,班组推进者!D:D,班组推进者!H:H,0) -> 齐张燕 | K3: =_xlfn.XLOOKUP(H3,班组推进者!D:D,班组推进者!I:I,0) -> 罗荣鑫 | N3: 在册 | O3: 3 | P3: 吴再胜 | Q3: 男 | R3: 450602197109074814 | S3: =YEAR(TODAY())-MID(R3,7,4) -> 55 | T3: 管工 | U3: 班组长 | V3: 自有 | W3: 46112 | Y3: 在职 | Z3: 作业负责人
A4: 2 | B4: BLE-NCES-002 | C4: 46108 | D4: 中建二局 | E4: 工程部 | F4: 四川金泰荣和建筑劳务有限公司 | G4: 王家纯/13828002135 | H4: 钟绍林木工班 | I4: 钟绍林/13219597969 | J4: =_xlfn.XLOOKUP(H4,班组推进者!D:D,班组推进者!H:H,0) -> 张翔、段龙飞 | K4: =_xlfn.XLOOKUP(H4,班组推进者!D:D,班组推进者!I:I,0) -> 刘友三 | N4: 在册 | O4: 5 | P4: 钟绍林 | Q4: 男 | R4: 511027196804047698 | S4: 58 | T4: 木工 | U4: 班组长 | V4: 非自有 | W4: 46108 | Y4: 在职 | Z4: 班组长
A5: 3 | B5: BLE-NCES-003 | C5: 46108 | D5: 中建二局 | E5: 工程部 | F5: 四川金泰荣和建筑劳务有限公司 | G5: 李传志/18877002381 | H5: 杨元帅混凝土班 | I5: 杨元帅/13828010148 | J5: 王支泽 | K5: 刘友三 | N5: 在册 | O5: 8 | P5: 杨元帅 | Q5: 男 | R5: 532927197308190573 | S5: 52 | T5: 混凝土工 | U5: 班组长 | V5: 非自有 | W5: 46108 | Y5: 在职 | Z5: 班组长
A6: 4 | B6: BLE-NCES-004 | C6: 46109 | D6: 中建二局 | E6: 工程部 | F6: 上海益江建设工程有限公司 | G6: 姚定胜/19812492786 | H6: 叶仁学综合班 | I6: 叶仁学/15380508611 | J6: 王支泽 | K6: 刘友三 | N6: 在册 | O6: 16 | P6: 叶仁学 | Q6: 男 | R6: 320923198805260913 | S6: 37 | T6: 技术员 | U6: 班组长 | V6: 非自有 | W6: 46109 | Y6: 在职 | Z6: 班组长
